Workbook

Sheet Entradas
A1: Entradas del modelo (celdas editables)
A2: Valores ASSUMED alineados con las 12 capas de la línea de quesos (3 tinas, 7 lotes al día, maduración de 150 días). Reemplazar por datos reales cuando existan y actualizar la columna Origen.
A4: A. Parámetros generales
A5: ID / ref. | B5: Parámetro | C5: Unidad | D5: Valor | G5: Origen | H5: Nota
A6: DEM-01 | B6: Demanda total de queso | C6: kg/día | D6: 3000 | G6: ASSUMED | H6: Demanda de ejemplo de las convenciones del modelo. Las capas dicen que capacidad y demanda son independientes; el plan de las capas produce 3.510 kg/día (7 lotes).
A7: Capa 10 | B7: Turnos por día | C7: turnos/día | D7: 2 | G7: ASSUMED | H7: Capa 9: 2 turnos de 8 h.
A8: Capa 9 §8 | B8: Horas por turno | C8: h/turno | D8: 8 | G8: ASSUMED | H8: Capa 9: 2 turnos de 8 h.
A9: Capa 9 §8 | B9: Días operativos por semana | C9: días/sem | D9: 6 | G9: ASSUMED | H9: Capa 9: 6 días de producción por semana.
A10: Capa 5 | B10: Equipos restrictivos en paralelo (tinas de cuajada) | C10: unidades | D10: 3 | G10: ASSUMED | H10: Capa 5 y Capa 9: 3 tinas de 5.000 L con 4.500 kg útiles.
A11: Q-TMP-023 | B11: Tiempo de cambio de producto | C11: min/cambio | D11: 30 | G11: ASSUMED | H11: Q-TMP-023 está pendiente en las capas. Supuesto del modelo de indicadores.
A12: — | B12: MTBF (tiempo medio entre fallas) | C12: h | D12: 22 | G12: ASSUMED | H12: Supuesto del modelo de indicadores. Junto con MTTR, RE y SE da un OEE cercano a la eficiencia global base de 65 % de la Capa 9.
A13: — | B13: MTTR (tiempo medio de reparación) | C13: h | D13: 4 | G13: ASSUMED | H13: Supuesto del modelo de indicadores.
A14: — | B14: Tasa de eficiencia RE | C14: % | D14: 0.88 | G14: ASSUMED | H14: PE = RE × SE. Supuesto del modelo de indicadores.
A15: — | B15: Eficiencia en velocidad SE | C15: % | D15: 0.92 | G15: ASSUMED | H15: SE = tiempo de ciclo diseñado / tiempo de ciclo real.
A16: Q-RES-001 a 006 | B16: Personas por turno (total de la línea) | C16: personas | D16: 10 | G16: ASSUMED | H16: Capa 10: 10 personas por turno (1 en recepción y tratamiento térmico, 3 en elaboración, 3 en empaque, 1 en calidad, 1 supervisor y 1 en limpieza).
A17: — | B17: Densidad de la leche | C17: kg/L | D17: 1.03 | G17: REFERENCE | H17: Valor usado en el análisis de UHT y en las capas (Capa 1).
A19: B. Parámetros por producto
A20: ID / ref. | B20: Parámetro | C20: Unidad | D20: Campesino (Q-PRD-001) | E20: Mozzarella (Q-PRD-002) | F20: Sopó (Q-PRD-003) | G20: Origen | H20: Nota
A21: DEM-02 | B21: Mezcla de demanda | C21: % | D21: 0.462 | E21: 0.282 | F21: 0.256 | G21: CALCULATED | H21: Reparto de masa del plan de las capas: 1.620, 990 y 900 kg de 3.510 kg (46 / 28 / 26 %). Debe sumar 100 %.
A22: Q-CAP-001 | B22: Tamaño de lote (leche procesada) | C22: kg leche/lote | D22: 4500 | E22: 4500 | F22: 4500 | G22: ASSUMED | H22: Capa 9: 4.500 kg de leche por lote (≈ 4.370 L).
A23: Q-CAP-011 | B23: Rendimiento del proceso | C23: kg queso/kg leche | D23: 0.12 | E23: 0.11 | F23: 0.1 | G23: ASSUMED | H23: Capa 9: 540, 495 y 450 kg de queso por lote; ponderado 0,111.
A24: — | B24: Rechazo / producto defectuoso | C24: % | D24: 0.02 | E24: 0.02 | F24: 0.02 | G24: ASSUMED | H24: No está en las capas. Supuesto del modelo de indicadores: Q = 1 − rechazo.
A25: Q-TMP-026 | B25: Ocupación de la tina, sin preparación ni limpieza | C25: h/lote | D25: 2.9 | E25: 2.9 | F25: 3.4 | G25: CALCULATED | H25: Capa 8: la tina se ocupa 224 min (campesino y mozzarella) y 254 min (Sopó). Se restan los 50 min de CIP: 174 y 204 min.
A26: Q-TMP-021 | B26: Preparación del equipo | C26: min/lote | D26: 0 | E26: 0 | F26: 0 | G26: ASSUMED | H26: Capa 8: va incluida en el llenado de la tina (54 min con el tratamiento térmico).
A27: Q-TMP-022 | B27: Limpieza del equipo (CIP) | C27: min/lote | D27: 50 | E27: 50 | F27: 50 | G27: ASSUMED | H27: Capa 8: CIP de la tina, 50 min por lote.
A28: Q-TMP-003 | B28: Almacenamiento de leche antes del proceso | C28: h | D28: 12 | E28: 12 | F28: 12 | G28: ASSUMED | H28: Capa 8: ≈ 12 h en promedio a ≤ 4 °C.
A29: Q-TMP-027* | B29: Fabricación activa del lote (sin enfriamiento, maduración ni liberación) | C29: h/lote | D29: 4.2 | E29: 5.2 | F29: 41.1 | G29: CALCULATED / ASSUMED | H29: Capa 8: ≈ 4,2 h (campesino) y ≈ 41,1 h (Sopó, incluye ≈ 36 h de salmuera). Mozzarella: 4,2 h más ≈ 1 h de estirado.
A30: Q-TMP-024 | B30: Esperas y oreo | C30: h/lote | D30: 0 | E30: 0.5 | F30: 12 | G30: ASSUMED | H30: Capa 8: mozzarella 30 min entre el enfriamiento y el empaque; Sopó, oreo de ≈ 12 h tras la salmuera.
A31: Q-TMP-017 | B31: Enfriamiento y acondicionamiento | C31: h/lote | D31: 12 | E31: 1.25 | F31: 2.5 | G31: ASSUMED | H31: Capa 8: campesino ≈ 12 h en refrigeración; mozzarella ≈ 75 min; Sopó ≈ 150 min.
A32: Q-TMP-016 | B32: Maduración | C32: días | D32: 0 | E32: 0 | F32: 150 | G32: ASSUMED | H32: Capa 8: Sopó ≈ 5 meses (150 días) a 9–11 °C. Solo el Sopó madura.
A33: Q-TMP-019 | B33: Retención hasta la liberación (producto terminado) | C33: h | D33: 72 | E33: 72 | F33: 120 | G33: ASSUMED | H33: Capa 8: 3 días (campesino y mozzarella) y 5 días (Sopó).
B34: Control: suma de la mezcla de demanda | D34: =SUM(D21:F21) -> 1 | E34: =IF(ROUND(D34,6)=1,"OK","La mezcla debe sumar 100 %") -> OK

Sheet Cálculos
A1: Cálculos
A2: Todo son fórmulas; las entradas viven en la hoja Entradas. Resultados válidos solo mientras las entradas sean supuestos.
A4: 1. Demanda, lotes y balance de masa
A5: ID / ref. | B5: Concepto | C5: Unidad | D5: Campesino | E5: Mozzarella | F5: Sopó | G5: Línea / total | H5: Fórmula o nota
A6: DEM-03 | B6: Demanda del producto | C6: kg/día | D6: =Entradas!$D$6*Entradas!D21 -> 1386 | E6: =Entradas!$D$6*Entradas!E21 -> 846 | F6: =Entradas!$D$6*Entradas!F21 -> 768 | G6: =SUM(D6:F6) -> 3000 | H6: Demanda total × mezcla
A7: Q-CAP-001 | B7: Leche procesada por lote | C7: kg leche/lote | D7: =Entradas!D22 -> 4500 | E7: =Entradas!E22 -> 4500 | F7: =Entradas!F22 -> 4500
A8: Q-CAP-004 | B8: Producción obtenida por lote | C8: kg queso/lote | D8: =D7*Entradas!D23 -> 540 | E8: =E7*Entradas!E23 -> 495 | F8: =F7*Entradas!F23 -> 450 | H8: Leche por lote × rendimiento
A9: — | B9: Producción buena por lote | C9: kg queso/lote | D9: =D8*(1-Entradas!D24) -> 529.2 | E9: =E8*(1-Entradas!E24) -> 485.1 | F9: =F8*(1-Entradas!F24) -> 441 | H9: Descuenta el rechazo
A10: — | B10: Lotes requeridos por día (enteros) | C10: lotes/día | D10: =ROUNDUP(D6/D9,0) -> 3 | E10: =ROUNDUP(E6/E9,0) -> 2 | F10: =ROUNDUP(F6/F9,0) -> 2 | G10: =SUM(D10:F10) -> 7 | H10: Se redondea hacia arriba: no se produce medio lote
A11: — | B11: Lotes teóricos (continuos) | C11: lotes/día | D11: =D6/D9 -> 2.6190476 | E11: =E6/E9 -> 1.7439703 | F11: =F6/F9 -> 1.7414966 | G11: =SUM(D11:F11) -> 6.1045145
A12: — | B12: Producción buena planificada | C12: kg/día | D12: =D10*D9 -> 1587.6 | E12: =E10*E9 -> 970.2 | F12: =F10*F9 -> 882 | G12: =SUM(D12:F12) -> 3439.8
A13: — | B13: Sobreproducción por lotes enteros | C13: % | D13: =D12/D6-1 -> 0.14545455 | E13: =E12/E6-1 -> 0.14680851 | F13: =F12/F6-1 -> 0.1484375 | G13: =G12/G6-1 -> 0.1466
A14: — | B14: Leche requerida | C14: kg/día | D14: =D10*D7 -> 13500 | E14: =E10*E7 -> 9000 | F14: =F10*F7 -> 9000 | G14: =SUM(D14:F14) -> 31500
A15: — | B15: Leche requerida | C15: L/día | D15: =D14/Entradas!$D$17 -> 13106.796 | E15: =E14/Entradas!$D$17 -> 8737.8641 | F15: =F14/Entradas!$D$17 -> 8737.8641 | G15: =SUM(D15:F15) -> 30582.524
A16: Q-CAP-011 | B16: Rendimiento del proceso (eficiencia física) | C16: kg/kg | D16: =Entradas!D23 -> 0.12 | E16: =Entradas!E23 -> 0.11 | F16: =Entradas!F23 -> 0.1 | G16: =SUMPRODUCT($D$10:$F$10,$D$8:$F$8)/G14 -> 0.11142857 | H16: Salida MP / entrada MP (García). Total: ponderado por lotes
A17: — | B17: Suero y otras salidas (leche − queso) | C17: kg/día | D17: =D14-D10*D8 -> 11880 | E17: =E14-E10*E8 -> 8010 | F17: =F14-F10*F8 -> 8100 | G17: =SUM(D17:F17) -> 27990 | H17: Balance de masa: no toda la leche se vuelve queso
A19: 2. Tiempo disponible y OEE (por equipo restrictivo, minutos por día)
A20: ID / ref. | B20: Concepto | C20: Unidad | D20: Campesino | E20: Mozzarella | F20: Sopó | G20: Línea / total | H20: Fórmula o nota
A21: Capa 5 | B21: Equipos restrictivos en paralelo (n) | C21: unidades | G21: =Entradas!$D$10 -> 3
A22: — | B22: Tiempo total por equipo (Tt) | C22: min/día | G22: =Entradas!$D$7*Entradas!$D$8*60 -> 960 | H22: Turnos × horas × 60
A23: — | B23: Cambios de producto por equipo | C23: cambios/día | G23: =MAX(COUNTIF(Entradas!D21:F21,">0")-1,0) -> 2 | H23: Productos activos − 1
A24: — | B24: Inactividad planeada por equipo (Tip) | C24: min/día | G24: =SUMPRODUCT($D$10:$F$10,Entradas!D26:F26+Entradas!D27:F27)/G21+G23*Entradas!$D$11 -> 176.66667 | H24: Preparación + limpieza de todos los lotes repartidos entre n equipos, más cambios de producto
A25: — | B25: Tiempo de ejecución planeado (Tep = Tt − Tip) | C25: min/día | G25: =G22-G24 -> 783.33333
A26: — | B26: Disponibilidad A = MTBF / (MTBF + MTTR) | C26: % | G26: =Entradas!$D$12/(Entradas!$D$12+Entradas!$D$13) -> 0.84615385 | H26: Equivale a Ter / Tep
A27: — | B27: Tiempo de ejecución real (Ter = TD neto) | C27: min/día | G27: =G25*G26 -> 662.82051 | H27: Tiempo neto disponible tras paradas planeadas y no planeadas
A28: — | B28: Inactividad no planeada (Tnp) | C28: min/día | G28: =G25-G27 -> 120.51282
A29: — | B29: Eficiencia de desempeño PE = RE × SE | C29: % | G29: =Entradas!$D$14*Entradas!$D$15 -> 0.8096
A30: — | B30: Tasa de calidad Q (ponderada por lotes) | C30: % | G30: =SUMPRODUCT($D$10:$F$10,$D$8:$F$8,1-Entradas!D24:F24)/SUMPRODUCT($D$10:$F$10,$D$8:$F$8) -> 0.98 | H30: (producción − defectuosos) / producción
A31: — | B31: OEE = A × PE × Q | C31: % | G31: =G26*G29*G30 -> 0.67134523 | H31: OEE de la línea con supuestos globales (MTBF, MTTR, RE, SE y rechazo iguales para los tres productos); por eso saldría igual por producto. No es una medición.
A33: 3. Takt y tiempo de ciclo
A34: ID / ref. | B34: Concepto | C34: Unidad | D34: Campesino | E34: Mozzarella | F34: Sopó | G34: Línea / total | H34: Fórmula o nota
A35: — | B35: Demanda en lotes (D) | C35: lotes/día | G35: =G10 -> 7
A36: — | B36: Takt T = TD / D | C36: min/lote | G36: =G27/G35 -> 94.688645 | H36: Tiempo neto disponible por equipo ÷ lotes requeridos
A37: — | B37: Takt por kg | C37: s/kg | G37: =G27*60/G6 -> 13.25641
A38: — | B38: Tiempo de ocupación diseñado (promedio ponderado) | C38: min/lote | G38: =SUMPRODUCT($D$10:$F$10,Entradas!D25:F25)*60/G35 -> 182.57143
A39: — | B39: Tiempo de ocupación real (÷ PE) | C39: min/lote | G39: =G38/G29 -> 225.50819 | H39: SE = tiempo diseñado / tiempo real
A40: Tc | B40: Ciclo efectivo de la etapa restrictiva (÷ n) | C40: min/lote | G40: =G39/G21 -> 75.169396 | H40: Con n equipos en paralelo sale un lote cada Tc
A41: — | B41: Margen Takt − Tc | C41: % | G41: =(G36-G40)/G36 -> 0.20614139
A42: — | B42: ¿Cumple el Takt? | C42: texto | G42: =IF(G40<=G36,"Cumple el Takt","No cumple: más equipos, ciclos más cortos o menor demanda") -> Cumple el Takt | H42: Solo se evalúa la etapa restrictiva compartida: las tinas (n = 3). El empaque, la prensa y el pasteurizador no entran en esta comprobación; el empaque se mide aparte, por empacadora.
A44: 4. Capacidad y utilización
...

Sheet Indicadores
A1: Indicadores — resumen
A2: Todos CALCULATED sobre entradas ASSUMED mientras no existan datos reales.
A4: Demanda y ritmo
A5: ID / ref. | B5: Indicador | C5: Valor | D5: Unidad | E5: Definición (curso / archivo) | F5: Origen
A6: DEM-01 | B6: Demanda total | C6: =Cálculos!G6 -> 3000 | D6: kg/día | E6: D = unidades requeridas por período | F6: CALCULATED
A7: — | B7: Lotes requeridos por día | C7: =Cálculos!G10 -> 7 | D7: lotes/día | E7: D en lotes, enteros | F7: CALCULATED
A8: — | B8: Takt | C8: =Cálculos!G36 -> 94.688645 | D8: min/lote | E8: T = TD / D | F8: CALCULATED
A9: — | B9: Takt por kg | C9: =Cálculos!G37 -> 13.25641 | D9: s/kg | E9: T = TD / D, por unidad de masa | F9: CALCULATED
A10: Tc | B10: Ciclo efectivo de la etapa restrictiva | C10: =Cálculos!G40 -> 75.169396 | D10: min/lote | E10: Ocupación real ÷ n equipos. Etapa restrictiva: las tinas | F10: CALCULATED
A11: — | B11: Margen Takt − Tc | C11: =Cálculos!G41 -> 0.20614139 | D11: % | E11: Positivo = cumple | F11: CALCULATED
A12: — | B12: ¿Cumple el Takt? | C12: =Cálculos!G42 -> Cumple el Takt | D12: texto | E12: Tc ≤ T. Aplica a las tinas, la etapa restrictiva compartida; no evalúa el empaque | F12: CALCULATED
A14: OEE
A15: ID / ref. | B15: Indicador | C15: Valor | D15: Unidad | E15: Definición (curso / archivo) | F15: Origen
A16: — | B16: Disponibilidad A | C16: =Cálculos!G26 -> 0.84615385 | D16: % | E16: A = Ter / Tep = MTBF / (MTBF + MTTR) | F16: CALCULATED
A17: — | B17: Eficiencia de desempeño PE | C17: =Cálculos!G29 -> 0.8096 | D17: % | E17: PE = RE × SE | F17: CALCULATED
A18: — | B18: Tasa de calidad Q | C18: =Cálculos!G30 -> 0.98 | D18: % | E18: Q = (producción − defectuosos) / producción | F18: CALCULATED
A19: — | B19: OEE | C19: =Cálculos!G31 -> 0.67134523 | D19: % | E19: OEE = A × PE × Q. Supuestos globales de la línea, iguales para los tres productos | F19: CALCULATED
A20: — | B20: Nivel de OEE (tabla de Cortés) | C20: =INDEX($B$53:$B$57,MATCH(C19,$A$53:$A$57,1)) -> Regular | D20: texto | E20: Ver tabla de niveles al final de esta hoja | F20: CALCULATED
A22: Capacidad y utilización
A23: ID / ref. | B23: Indicador | C23: Valor | D23: Unidad | E23: Definición (curso / archivo) | F23: Origen
A24: Q-CAP-012 | B24: Capacidad de la línea en operación | C24: =Cálculos!G52 -> 321.05035 | D24: kg/h | E24: Producción planificada ÷ horas de línea necesarias | F24: CALCULATED
A25: Q-CAP-007 | B25: Capacidad diaria con la mezcla planificada | C25: =Cálculos!G54 -> 4074.8698 | D25: kg/día | E25: Con pérdidas por cambios y fallas | F25: CALCULATED
A26: Q-CAP-006 | B26: Capacidad por turno | C26: =Cálculos!G55 -> 2037.4349 | D26: kg/turno | F26: CALCULATED
A27: Q-CAP-005 | B27: Capacidad por hora de calendario | C27: =Cálculos!G56 -> 254.67936 | D27: kg/h | F27: CALCULATED
A28: PC | B28: Capacidad nominal PC | C28: =Cálculos!G57 -> 7751.662 | D28: kg/día | E28: PC = n · S · H · Rp | F28: CALCULATED
A29: U | B29: Utilización U = Q / PC | C29: =Cálculos!G58 -> 0.44375 | D29: % | E29: Definición del curso | F29: CALCULATED
A30: Q-CAP-010 | B30: Utilización del equipo (uso efectivo / disponibilidad) | C30: =Cálculos!G59 -> 0.79385861 | D30: % | E30: Definición de la capa 9; distinta de la del curso | F30: CALCULATED
A31: — | B31: Sobreproducción por lotes enteros | C31: =Cálculos!G13 -> 0.1466 | D31: % | E31: Producción planificada sobre demanda | F31: CALCULATED
A33: Rendimiento y productividad (García)
A34: ID / ref. | B34: Indicador | C34: Valor | D34: Unidad | E34: Definición (curso / archivo) | F34: Origen
A35: Q-CAP-011 | B35: Eficiencia física (salida MP / entrada MP) | C35: =Cálculos!G16 -> 0.11142857 | D35: kg/kg | E35: Ef = salida MP / entrada MP | F35: CALCULATED
A36: — | B36: Suero y otras salidas | C36: =Cálculos!G17 -> 27990 | D36: kg/día | E36: Leche − queso | F36: CALCULATED
A37: — | B37: Productividad de materia prima | C37: =Cálculos!G12/Cálculos!G14 -> 0.1092 | D37: kg bueno/kg leche | E37: Salida buena / entrada de leche | F37: CALCULATED
A38: — | B38: Productividad de mano de obra | C38: =Cálculos!G12/(Entradas!$D$16*Entradas!$D$7) -> 171.99 | D38: kg/persona-turno | E38: Salida buena / (personas por turno × turnos) | F38: CALCULATED
A39: — | B39: Eficiencia económica | C39: Pendiente: requiere precios y costos | D39: — | E39: Ee = ventas / costos | F39: PENDING
A41: MLT y valor agregado por producto
A42: ID / ref. | B42: Indicador | C42: Valor | D42: Unidad | E42: Definición (curso / archivo) | F42: Origen
A43: Q-TMP-027 | B43: MLT — Campesino | C43: =Cálculos!D71 -> 4.175 | D43: días | E43: Tsu + Σ(Tc + Tno) + enfriamiento + maduración + retención | F43: CALCULATED
A44: Q-TMP-027 | B44: MLT — Mozzarella | C44: =Cálculos!E71 -> 3.7895833 | D44: días | E44: Tsu + Σ(Tc + Tno) + enfriamiento + maduración + retención | F44: CALCULATED
A45: Q-TMP-027 | B45: MLT — Sopó | C45: =Cálculos!F71 -> 157.81667 | D45: días | E45: Tsu + Σ(Tc + Tno) + enfriamiento + maduración + retención | F45: CALCULATED
...

Sheet Contraste con capas
A1: Contraste del modelo con las 12 capas
A2: Valor que sale del modelo frente al valor registrado en las capas. Las diferencias pequeñas se explican en la última columna.
A4: Indicador | B4: Modelo | C4: Capas | D4: Comentario
A5: Lotes por día | B5: =Cálculos!G10 -> 7 | C5: 7 (3 + 2 + 2) | D5: Coinciden: la mezcla del plan de las capas da 3, 2 y 2 lotes.
A6: Tinas | B6: =Entradas!D10 -> 3 | C6: 3 | D6: Capa 5 y Capa 9.
A7: Producción buena planificada (kg/día) | B7: =Cálculos!G12 -> 3439.8 | C7: 3.510 kg/día | D7: El modelo descuenta el rechazo de 2 %, que las capas no tienen.
A8: Leche requerida (kg/día) | B8: =Cálculos!G14 -> 31500 | C8: 31.500 kg/día | D8: Siete lotes de 4.500 kg.
A9: Rendimiento ponderado (kg/kg) | B9: =Cálculos!G16 -> 0.11142857 | C9: 0,111 | D9: Q-CAP-011.
A10: Capacidad por hora de calendario (kg/h) | B10: =Cálculos!G56 -> 254.67936 | C10: ≈ 219 kg/h | D10: Las capas dividen 3.510 kg entre 16 h, sin descontar paradas; el modelo sí las descuenta.
A11: OEE | B11: =Cálculos!G31 -> 0.67134523 | C11: ≈ 65 % (eficiencia global base) | D11: El OEE sale de A × PE × Q con MTBF, MTTR, RE y SE supuestos; las capas parten del 65 % directo.
A12: Utilización del equipo (Q-CAP-010) | B12: =Cálculos!G59 -> 0.79385861 | C12: 87 % (tinas) | D12: Ver nota al pie: ambos usan las mismas 27,1 h de tina por día, pero distinto tiempo disponible. No es un error; no requiere cambios en las capas.
A13: Inventario en maduración (kg) | B13: =Cálculos!G74 -> 113400 | C13: ≈ 116.000 kg | D13: Las capas usan 900 kg diarios; el modelo usa la producción buena diaria.
A14: Producto terminado en retención (kg) | B14: =Cálculos!G75 -> 12083.4 | C14: ≈ 12.300 kg | D14: Q-CAP-008: 2.610 kg de frescos × 3 días + 900 kg de Sopó × 5 días.
A15: MLT campesino (días) | B15: =Cálculos!D71 -> 4.175 | C15: ≈ 4,2 | D15: Tiempo hasta la liberación, sin empaque en las capas.
A16: MLT mozzarella (días) | B16: =Cálculos!E71 -> 3.7895833 | C16: ≈ 3,8
A17: MLT Sopó (días) | B17: =Cálculos!F71 -> 157.81667 | C17: ≈ 158 | D17: Incluye 150 días de maduración.
A18: Personas por turno | B18: =Entradas!D16 -> 10 | C18: 10 | D18: Capa 10.
A20: Nota sobre la utilización de las tinas (87 % frente a 79 %)
A21: Ambos cálculos parten de la misma carga: 27,1 h de tina al día (3×224 + 2×224 + 2×254 min). Capas: 27,1 h / (3 tinas × 16 h × 65 % de eficiencia global) = 27,1 / 31,2 h = 87 %. Modelo: la carga se divide entre PE (0,81) y el tiempo disponible solo descuenta cambios de producto y fallas (aprox. 42 h entre las tres tinas), por eso sale 79 %. La diferencia es de definición del tiempo disponible, no un error. Para los cálculos se usa el valor del modelo y las capas no necesitan cambios; al citar cifras, indicar qué definición se usa.

Sheet Cambios vs versión del equipo
A1: Qué cambió respecto al modelo del equipo
A2: Se conservan la estructura, las fórmulas y los indicadores. Cambian las entradas, para que coincidan con las 12 capas.
A4: Parámetro | B4: Modelo del equipo | C4: Esta versión (capas) | D4: Por qué
A5: Tinas | B5: 3 (archivo adjunto) o 4 (versión «realista» del md) | C5: 3 | D5: Capa 5 y Capa 9: 3 tinas de 5.000 L.
A6: Lotes por día | B6: 8 (3 + 3 + 2) | C6: 7 (3 + 2 + 2) | D6: Sale de la mezcla de las capas; no se fuerza.
A7: Mezcla de demanda | B7: 40 / 35 / 25 % | C7: 46 / 28 / 26 % | D7: Reparto de masa del plan diario de las capas.
A8: Rendimiento | B8: 0,105 / 0,10 / 0,095 (versión realista) | C8: 0,12 / 0,11 / 0,10 | D8: Capa 9, Q-CAP-011.
A9: Ocupación de la tina (sin CIP ni preparación) | B9: 3,5 / 4,0 / 3,5 h | C9: 2,9 / 2,9 / 3,4 h | D9: Capa 8: 224 / 224 / 254 min incluyen 50 min de CIP.
A10: Preparación del equipo | B10: 20 o 30 min | C10: 0 min | D10: Capa 8: va incluida en el llenado de la tina.
A11: CIP | B11: 45 min | C11: 50 min | D11: Capa 8.
A12: Personas por turno | B12: 6 | C12: 10 | D12: Capa 10.
A13: Maduración del Sopó | B13: 30 días | C13: 150 días | D13: Capa 8: ≈ 5 meses.
A14: Fabricación activa | B14: 5 / 5,5 / 5 h | C14: 4,2 / 5,2 / 41,1 h | D14: Capa 8; el Sopó incluye ≈ 36 h de salmuera.
A15: Retención hasta la liberación | B15: 24 h | C15: 72 / 72 / 120 h | D15: Capa 8: 3 días (frescos) y 5 días (Sopó).
... A18: MTBF, MTTR, RE, SE, rechazo, cambio de producto | B18: Supuestos del equipo | C18: 22 h, 4 h, 88 %, 92 %, 2 %, 30 min | D18: No están en las capas; se dejan como supuestos del modelo de indicadores (la versión realista con 22/4/88/92).
